<?xml version="1.0" ?>
<!-- =================================================================================== -->
<!-- |    This document was autogenerated by xacro from omtp_custom_factory.urdf.xacro | -->
<!-- |    EDITING THIS FILE BY HAND IS NOT RECOMMENDED                                 | -->
<!-- =================================================================================== -->
<!-- =================================================================================== -->
<!-- |    This document was autogenerated by xacro from omtp_factory.xacro             | -->
<!-- |    EDITING THIS FILE BY HAND IS NOT RECOMMENDED                                 | -->
<!-- =================================================================================== -->
<robot name="omtp_factory">
  <!-- ==================================================== -->
  <!-- INITIAL SETUP OF WORLD LINK AND WORLD_INTERFACE LINK -->
  <!-- ==================================================== -->
  <!-- world -->
  <link name="world"/>
  <!-- world_interface. Makes it convenient to move the whole environment according to the world origin -->
  <link name="world_interface"/>
  <!-- world<->world_interface joint -->
  <joint name="world_interface_to_world" type="fixed">
    <parent link="world"/>
    <child link="world_interface"/>
  </joint>
  <!-- <xacro:include filename="$(find aau_lab_ros_models)/urdf/fib14/fib14.urdf.xacro"/>
  <xacro:fib14_urdf fib14_parent="world_interface"/> -->
  <!-- <xacro:arg name="arm_id_1" default="panda_1" />
  <xacro:arg name="arm_id_2" default="panda_2" />

  <xacro:include filename="$(find franka_description)/robots/panda_arm.xacro"/>
  <xacro:include filename="$(find franka_description)/robots/hand.xacro"/>
  
  <xacro:panda_arm arm_id="$(arg arm_id_1)" connected_to="${robot1_pedestal_link}"  xyz="${0 -0.5 1}" safety_distance="0.03"/>
  <xacro:hand ns="$(arg arm_id_1)" rpy="0 0 ${-pi/4}" connected_to="$(arg arm_id_1)_link8" safety_distance="0.03"/> -->
  <!-- Load gazebo control -->
  <joint name="panda1_virtual_joint" type="fixed">
    <parent link="robot1_pedestal_link"/>
    <child link="panda1_link0"/>
    <origin rpy="0 0 0" xyz="0.05 0 0.95"/>
    <dynamics damping="1.0"/>
  </joint>
  <link name="panda1_link0">
    <visual>
      <geometry>
        <mesh filename="file:///home/lass6230/github/OMTP_excersizes/lecture_1/install/franka_description/share/franka_description/meshes/visual/link0.dae"/>
      </geometry>
    </visual>
    <collision>
      <origin rpy="0 0 0" xyz="0 0 -0.1915"/>
      <geometry>
        <cylinder length="0.2830" radius="0.09"/>
      </geometry>
    </collision>
    <collision>
      <origin rpy="0 0 0" xyz="0 0 -0.333"/>
      <geometry>
        <sphere radius="0.09"/>
      </geometry>
    </collision>
    <collision>
      <origin rpy="0 0 0" xyz="0 0 -0.05"/>
      <geometry>
        <sphere radius="0.09"/>
      </geometry>
    </collision>
    <inertial>
      <origin rpy="0 0 0" xyz="0 0 0"/>
      <mass value="3.06"/>
      <inertia ixx="0.3" ixy="0.0" ixz="0.0" iyy="0.3" iyz="0.0" izz="0.3"/>
    </inertial>
  </link>
  <link name="panda1_link1">
    <visual>
      <geometry>
        <mesh filename="file:///home/lass6230/github/OMTP_excersizes/lecture_1/install/franka_description/share/franka_description/meshes/visual/link1.dae"/>
      </geometry>
    </visual>
    <collision>
      <origin rpy="0 0 0" xyz="0 0 -0.1915"/>
      <geometry>
        <cylinder length="0.2830" radius="0.09"/>
      </geometry>
    </collision>
    <collision>
      <origin rpy="0 0 0" xyz="0 0 -0.333"/>
      <geometry>
        <sphere radius="0.09"/>
      </geometry>
    </collision>
    <collision>
      <origin rpy="0 0 0" xyz="0 0 -0.05"/>
      <geometry>
        <sphere radius="0.09"/>
      </geometry>
    </collision>
    <inertial>
      <origin rpy="0 0 0" xyz="0 0 0"/>
      <mass value="2.34"/>
      <inertia ixx="0.3" ixy="0.0" ixz="0.0" iyy="0.3" iyz="0.0" izz="0.3"/>
    </inertial>
  </link>
  <link name="panda1_link2">
    <visual>
      <geometry>
        <mesh filename="file:///home/lass6230/github/OMTP_excersizes/lecture_1/install/franka_description/share/franka_description/meshes/visual/link2.dae"/>
      </geometry>
    </visual>
    <collision>
      <origin rpy="0 0 0" xyz="0 0 0"/>
      <geometry>
        <cylinder length="0.12" radius="0.09"/>
      </geometry>
    </collision>
    <collision>
      <origin rpy="0 0 0" xyz="0 0 -0.06"/>
      <geometry>
        <sphere radius="0.09"/>
      </geometry>
    </collision>
    <collision>
      <origin rpy="0 0 0" xyz="0 0 0.06"/>
      <geometry>
        <sphere radius="0.09"/>
      </geometry>
    </collision>
    <inertial>
      <origin rpy="0 0 0" xyz="0 0 0"/>
      <mass value="2.36"/>
      <inertia ixx="0.3" ixy="0.0" ixz="0.0" iyy="0.3" iyz="0.0" izz="0.3"/>
    </inertial>
  </link>
  <link name="panda1_link3">
    <visual>
      <geometry>
        <mesh filename="file:///home/lass6230/github/OMTP_excersizes/lecture_1/install/franka_description/share/franka_description/meshes/visual/link3.dae"/>
      </geometry>
    </visual>
    <collision>
      <origin rpy="0 0 0" xyz="0 0 -0.145"/>
      <geometry>
        <cylinder length="0.15" radius="0.09"/>
      </geometry>
    </collision>
    <collision>
      <origin rpy="0 0 0" xyz="0 0 -0.22"/>
      <geometry>
        <sphere radius="0.09"/>
      </geometry>
    </collision>
    <collision>
      <origin rpy="0 0 0" xyz="0 0 -0.07"/>
      <geometry>
        <sphere radius="0.09"/>
      </geometry>
    </collision>
    <inertial>
      <origin rpy="0 0 0" xyz="0 0 0"/>
      <mass value="2.38"/>
      <inertia ixx="0.3" ixy="0.0" ixz="0.0" iyy="0.3" iyz="0.0" izz="0.3"/>
    </inertial>
  </link>
  <link name="panda1_link4">
    <visual>
      <geometry>
        <mesh filename="file:///home/lass6230/github/OMTP_excersizes/lecture_1/install/franka_description/share/franka_description/meshes/visual/link4.dae"/>
      </geometry>
    </visual>
    <collision>
      <origin rpy="0 0 0" xyz="0 0 0"/>
      <geometry>
        <cylinder length="0.12" radius="0.09"/>
      </geometry>
    </collision>
    <collision>
      <origin rpy="0 0 0" xyz="0 0 0.06"/>
      <geometry>
        <sphere radius="0.09"/>
      </geometry>
    </collision>
    <collision>
      <origin rpy="0 0 0" xyz="0 0 -0.06"/>
      <geometry>
        <sphere radius="0.09"/>
      </geometry>
    </collision>
    <inertial>
      <origin rpy="0 0 0" xyz="0 0 0"/>
      <mass value="2.43"/>
      <inertia ixx="0.3" ixy="0.0" ixz="0.0" iyy="0.3" iyz="0.0" izz="0.3"/>
    </inertial>
  </link>
  <link name="panda1_link5">
    <visual>
      <geometry>
        <mesh filename="file:///home/lass6230/github/OMTP_excersizes/lecture_1/install/franka_description/share/franka_description/meshes/visual/link5.dae"/>
      </geometry>
    </visual>
    <collision>
      <origin rpy="0 0 0" xyz="0 0 -0.26"/>
      <geometry>
        <cylinder length="0.1" radius="0.09"/>
      </geometry>
    </collision>
    <collision>
      <origin rpy="0 0 0" xyz="0 0 -0.31"/>
      <geometry>
        <sphere radius="0.09"/>
      </geometry>
    </collision>
    <collision>
      <origin rpy="0 0 0" xyz="0 0 -0.21"/>
      <geometry>
        <sphere radius="0.09"/>
      </geometry>
    </collision>
    <collision>
      <origin rpy="0 0 0" xyz="0 0.08 -0.13"/>
      <geometry>
        <cylinder length="0.14" radius="0.055"/>
      </geometry>
    </collision>
    <collision>
      <origin rpy="0 0 0" xyz="0 0.08 -0.06"/>
      <geometry>
        <sphere radius="0.055"/>
      </geometry>
    </collision>
    <collision>
      <origin rpy="0 0 0" xyz="0 0.08 -0.20"/>
      <geometry>
        <sphere radius="0.055"/>
      </geometry>
    </collision>
    <inertial>
      <origin rpy="0 0 0" xyz="0 0 0"/>
      <mass value="3.5"/>
      <inertia ixx="0.3" ixy="0.0" ixz="0.0" iyy="0.3" iyz="0.0" izz="0.3"/>
    </inertial>
  </link>
  <link name="panda1_link6">
    <visual>
      <geometry>
        <mesh filename="file:///home/lass6230/github/OMTP_excersizes/lecture_1/install/franka_description/share/franka_description/meshes/visual/link6.dae"/>
      </geometry>
    </visual>
    <collision>
      <origin rpy="0 0 0" xyz="0 0 -0.03"/>
      <geometry>
        <cylinder length="0.08" radius="0.08"/>
      </geometry>
    </collision>
    <collision>
      <origin rpy="0 0 0" xyz="0 0 0.01"/>
      <geometry>
        <sphere radius="0.08"/>
      </geometry>
    </collision>
    <collision>
      <origin rpy="0 0 0" xyz="0 0 -0.07"/>
      <geometry>
        <sphere radius="0.08"/>
      </geometry>
    </collision>
    <inertial>
      <origin rpy="0 0 0" xyz="0 0 0"/>
      <mass value="1.47"/>
      <inertia ixx="0.3" ixy="0.0" ixz="0.0" iyy="0.3" iyz="0.0" izz="0.3"/>
    </inertial>
  </link>
  <link name="panda1_link7">
    <visual>
      <geometry>
        <mesh filename="file:///home/lass6230/github/OMTP_excersizes/lecture_1/install/franka_description/share/franka_description/meshes/visual/link7.dae"/>
      </geometry>
    </visual>
    <collision>
      <origin rpy="0 0 0" xyz="0 0 0.01"/>
      <geometry>
        <cylinder length="0.14" radius="0.07"/>
      </geometry>
    </collision>
    <collision>
      <origin rpy="0 0 0" xyz="0 0 0.08"/>
      <geometry>
        <sphere radius="0.07"/>
      </geometry>
    </collision>
    <collision>
      <origin rpy="0 0 0" xyz="0 0 -0.06"/>
      <geometry>
        <sphere radius="0.07"/>
      </geometry>
    </collision>
    <inertial>
      <origin rpy="0 0 0" xyz="0 0 0"/>
      <mass value="0.45"/>
      <inertia ixx="0.3" ixy="0.0" ixz="0.0" iyy="0.3" iyz="0.0" izz="0.3"/>
    </inertial>
  </link>
  <link name="panda1_link8">
    <collision>
      <origin rpy="3.141592653589793 1.5707963267948966 1.5707963267948966" xyz="0.0424 0.0424 -0.0250"/>
      <geometry>
        <cylinder length="0.01" radius="0.06"/>
      </geometry>
    </collision>
    <collision>
      <origin rpy="0 0 0" xyz="0.0424 0.0424 -0.02"/>
      <geometry>
        <sphere radius="0.06"/>
      </geometry>
    </collision>
    <collision>
      <origin rpy="0 0 0" xyz="0.0424 0.0424 -0.03"/>
      <geometry>
        <sphere radius="0.06"/>
      </geometry>
    </collision>
    <inertial>
      <origin rpy="0 0 0" xyz="0 0 0"/>
      <mass value="0.0"/>
      <inertia ixx="0.3" ixy="0.0" ixz="0.0" iyy="0.3" iyz="0.0" izz="0.3"/>
    </inertial>
  </link>
  <joint name="panda1_joint1" type="revolute">
    <safety_controller k_position="100.0" k_velocity="40.0" soft_lower_limit="-2.8973" soft_upper_limit="2.8973"/>
    <origin rpy="0 0 0" xyz="0 0 0.333"/>
    <parent link="panda1_link0"/>
    <child link="panda1_link1"/>
    <limit effort="87" lower="-2.8973" upper="2.8973" velocity="2.175"/>
    <axis xyz="0 0 1"/>
    <dynamics damping="1.0"/>
  </joint>
  <joint name="panda1_joint2" type="revolute">
    <safety_controller k_position="100.0" k_velocity="40.0" soft_lower_limit="-1.7628" soft_upper_limit="1.7628"/>
    <origin rpy="-1.5707963267948966 0 0" xyz="0 0 0"/>
    <parent link="panda1_link1"/>
    <child link="panda1_link2"/>
    <limit effort="87" lower="-1.7628" upper="1.7628" velocity="2.175"/>
    <axis xyz="0 0 1"/>
    <dynamics damping="1.0"/>
  </joint>
  <joint name="panda1_joint3" type="revolute">
    <safety_controller k_position="100.0" k_velocity="40.0" soft_lower_limit="-2.8973" soft_upper_limit="2.8973"/>
    <origin rpy="1.5707963267948966 0 0" xyz="0 -0.316 0"/>
    <parent link="panda1_link2"/>
    <child link="panda1_link3"/>
    <limit effort="87" lower="-2.8973" upper="2.8973" velocity="2.175"/>
    <axis xyz="0 0 1"/>
    <dynamics damping="1.0"/>
  </joint>
  <joint name="panda1_joint4" type="revolute">
    <safety_controller k_position="100.0" k_velocity="40.0" soft_lower_limit="-3.0718" soft_upper_limit="-0.0698"/>
    <origin rpy="1.5707963267948966 0 0" xyz="0.0825 0 0"/>
    <parent link="panda1_link3"/>
    <child link="panda1_link4"/>
    <limit effort="87" lower="-3.0718" upper="-0.0698" velocity="2.175"/>
    <axis xyz="0 0 1"/>
    <dynamics damping="1.0"/>
  </joint>
  <joint name="panda1_joint5" type="revolute">
    <safety_controller k_position="100.0" k_velocity="40.0" soft_lower_limit="-2.8973" soft_upper_limit="2.8973"/>
    <origin rpy="-1.5707963267948966 0 0" xyz="-0.0825 0.384 0"/>
    <parent link="panda1_link4"/>
    <child link="panda1_link5"/>
    <limit effort="12" lower="-2.8973" upper="2.8973" velocity="2.61"/>
    <axis xyz="0 0 1"/>
    <dynamics damping="1.0"/>
  </joint>
  <joint name="panda1_joint6" type="revolute">
    <safety_controller k_position="100.0" k_velocity="40.0" soft_lower_limit="-0.0175" soft_upper_limit="3.7525"/>
    <origin rpy="1.5707963267948966 0 0" xyz="0 0 0"/>
    <parent link="panda1_link5"/>
    <child link="panda1_link6"/>
    <limit effort="12" lower="-0.0175" upper="3.7525" velocity="2.61"/>
    <axis xyz="0 0 1"/>
    <dynamics damping="1.0"/>
  </joint>
  <joint name="panda1_joint7" type="revolute">
    <safety_controller k_position="100.0" k_velocity="40.0" soft_lower_limit="-2.8973" soft_upper_limit="2.8973"/>
    <origin rpy="1.5707963267948966 0 0" xyz="0.088 0 0"/>
    <parent link="panda1_link6"/>
    <child link="panda1_link7"/>
    <limit effort="12" lower="-2.8973" upper="2.8973" velocity="2.61"/>
    <axis xyz="0 0 1"/>
    <dynamics damping="1.0"/>
  </joint>
  <joint name="panda1_joint8" type="fixed">
    <origin rpy="0 0 0" xyz="0 0 0.107"/>
    <parent link="panda1_link7"/>
    <child link="panda1_link8"/>
    <axis xyz="0 0 0"/>
    <dynamics damping="1.0"/>
  </joint>
  <joint name="panda1_hand_joint" type="fixed">
    <parent link="panda1_link8"/>
    <child link="panda1_hand"/>
    <origin rpy="0 0 -0.7853981633974483" xyz="0 0 0"/>
  </joint>
  <link name="panda1_hand">
    <visual>
      <geometry>
        <mesh filename="file:///home/lass6230/github/OMTP_excersizes/lecture_1/install/franka_description/share/franka_description/meshes/visual/hand.dae"/>
      </geometry>
    </visual>
    <collision>
      <origin rpy="0 1.5707963267948966 1.5707963267948966" xyz="0 0 0.04"/>
      <geometry>
        <cylinder length="0.1" radius="0.07"/>
      </geometry>
    </collision>
    <collision>
      <origin rpy="0 0 0" xyz="0 -0.05 0.04"/>
      <geometry>
        <sphere radius="0.07"/>
      </geometry>
    </collision>
    <collision>
      <origin rpy="0 0 0" xyz="0 0.05 0.04"/>
      <geometry>
        <sphere radius="0.07"/>
      </geometry>
    </collision>
    <collision>
      <origin rpy="0 1.5707963267948966 1.5707963267948966" xyz="0 0 0.1"/>
      <geometry>
        <cylinder length="0.1" radius="0.05"/>
      </geometry>
    </collision>
    <collision>
      <origin rpy="0 0 0" xyz="0 -0.05 0.1"/>
      <geometry>
        <sphere radius="0.05"/>
      </geometry>
    </collision>
    <collision>
      <origin rpy="0 0 0" xyz="0 0.05 0.1"/>
      <geometry>
        <sphere radius="0.05"/>
      </geometry>
    </collision>
    <inertial>
      <origin rpy="0 0 0" xyz="0 0 0"/>
      <mass value="0.48"/>
      <inertia ixx="0.1" ixy="0.0" ixz="0.0" iyy="0.1" iyz="0.0" izz="0.1"/>
    </inertial>
  </link>
  <link name="panda1_leftfinger">
    <visual>
      <geometry>
        <mesh filename="file:///home/lass6230/github/OMTP_excersizes/lecture_1/install/franka_description/share/franka_description/meshes/visual/finger.dae"/>
      </geometry>
    </visual>
    <inertial>
      <origin rpy="0 0 0" xyz="0 0 0"/>
      <mass value="0.1"/>
      <inertia ixx="0.1" ixy="0.0" ixz="0.0" iyy="0.1" iyz="0.0" izz="0.1"/>
    </inertial>
  </link>
  <link name="panda1_rightfinger">
    <visual>
      <origin rpy="0 0 3.141592653589793" xyz="0 0 0"/>
      <geometry>
        <mesh filename="file:///home/lass6230/github/OMTP_excersizes/lecture_1/install/franka_description/share/franka_description/meshes/visual/finger.dae"/>
      </geometry>
    </visual>
    <inertial>
      <origin rpy="0 0 3.141592653589793" xyz="0 0 0"/>
      <mass value="0.1"/>
      <inertia ixx="0.1" ixy="0.0" ixz="0.0" iyy="0.1" iyz="0.0" izz="0.1"/>
    </inertial>
  </link>
  <joint name="panda1_finger_joint1" type="prismatic">
    <parent link="panda1_hand"/>
    <child link="panda1_leftfinger"/>
    <origin rpy="0 0 0" xyz="0 0 0.0584"/>
    <axis xyz="0 1 0"/>
    <limit effort="150" lower="0.0" upper="0.04" velocity="0.2"/>
  </joint>
  <joint name="panda1_finger_joint2" type="prismatic">
    <parent link="panda1_hand"/>
    <child link="panda1_rightfinger"/>
    <origin rpy="0 0 0" xyz="0 0 0.0584"/>
    <axis xyz="0 -1 0"/>
    <limit effort="150" lower="0.0" upper="0.04" velocity="0.2"/>
  </joint>
  <gazebo reference="panda1_link0">
    <material>Gazebo/White</material>
    <mu1>0.2</mu1>
    <mu2>0.2</mu2>
  </gazebo>
  <gazebo reference="panda1_link1">
    <material>Gazebo/White</material>
    <mu1>0.2</mu1>
    <mu2>0.2</mu2>
  </gazebo>
  <gazebo reference="panda1_link2">
    <material>Gazebo/White</material>
    <mu1>0.2</mu1>
    <mu2>0.2</mu2>
  </gazebo>
  <gazebo reference="panda1_link3">
    <material>Gazebo/White</material>
    <mu1>0.2</mu1>
    <mu2>0.2</mu2>
  </gazebo>
  <gazebo reference="panda1_link4">
    <material>Gazebo/White</material>
    <mu1>0.2</mu1>
    <mu2>0.2</mu2>
  </gazebo>
  <gazebo reference="panda1_link5">
    <material>Gazebo/White</material>
    <mu1>0.2</mu1>
    <mu2>0.2</mu2>
  </gazebo>
  <gazebo reference="panda1_link6">
    <material>Gazebo/White</material>
    <mu1>0.2</mu1>
    <mu2>0.2</mu2>
  </gazebo>
  <gazebo reference="panda1_link7">
    <material>Gazebo/White</material>
    <mu1>0.2</mu1>
    <mu2>0.2</mu2>
  </gazebo>
  <gazebo reference="panda1_link8">
    <material>Gazebo/White</material>
    <mu1>0.2</mu1>
    <mu2>0.2</mu2>
  </gazebo>
  <transmission name="panda1_tran_1">
    <type>transmission_interface/SimpleTransmission</type>
    <joint name="panda1_joint1">
      <hardwareInterface>hardware_interface/EffortJointInterface</hardwareInterface>
    </joint>
    <actuator name="panda1_motor_1">
      <hardwareInterface>hardware_interface/EffortJointInterface</hardwareInterface>
      <mechanicalReduction>1</mechanicalReduction>
    </actuator>
  </transmission>
  <transmission name="panda1_tran_2">
    <type>transmission_interface/SimpleTransmission</type>
    <joint name="panda1_joint2">
      <hardwareInterface>hardware_interface/EffortJointInterface</hardwareInterface>
    </joint>
    <actuator name="panda1_motor_2">
      <hardwareInterface>hardware_interface/EffortJointInterface</hardwareInterface>
      <mechanicalReduction>1</mechanicalReduction>
    </actuator>
  </transmission>
  <transmission name="panda1_tran_3">
    <type>transmission_interface/SimpleTransmission</type>
    <joint name="panda1_joint3">
      <hardwareInterface>hardware_interface/EffortJointInterface</hardwareInterface>
    </joint>
    <actuator name="panda1_motor_3">
      <hardwareInterface>hardware_interface/EffortJointInterface</hardwareInterface>
      <mechanicalReduction>1</mechanicalReduction>
    </actuator>
  </transmission>
  <transmission name="panda1_tran_4">
    <type>transmission_interface/SimpleTransmission</type>
    <joint name="panda1_joint4">
      <hardwareInterface>hardware_interface/EffortJointInterface</hardwareInterface>
    </joint>
    <actuator name="panda1_motor_4">
      <hardwareInterface>hardware_interface/EffortJointInterface</hardwareInterface>
      <mechanicalReduction>1</mechanicalReduction>
    </actuator>
  </transmission>
  <transmission name="panda1_tran_5">
    <type>transmission_interface/SimpleTransmission</type>
    <joint name="panda1_joint5">
      <hardwareInterface>hardware_interface/EffortJointInterface</hardwareInterface>
    </joint>
    <actuator name="panda1_motor_5">
      <hardwareInterface>hardware_interface/EffortJointInterface</hardwareInterface>
      <mechanicalReduction>1</mechanicalReduction>
    </actuator>
  </transmission>
  <transmission name="panda1_tran_6">
    <type>transmission_interface/SimpleTransmission</type>
    <joint name="panda1_joint6">
      <hardwareInterface>hardware_interface/EffortJointInterface</hardwareInterface>
    </joint>
    <actuator name="panda1_motor_6">
      <hardwareInterface>hardware_interface/EffortJointInterface</hardwareInterface>
      <mechanicalReduction>1</mechanicalReduction>
    </actuator>
  </transmission>
  <transmission name="panda1_tran_7">
    <type>transmission_interface/SimpleTransmission</type>
    <joint name="panda1_joint7">
      <hardwareInterface>hardware_interface/EffortJointInterface</hardwareInterface>
    </joint>
    <actuator name="panda1_motor_7">
      <hardwareInterface>hardware_interface/EffortJointInterface</hardwareInterface>
      <mechanicalReduction>1</mechanicalReduction>
    </actuator>
  </transmission>
  <joint name="robot1_pedestal_joint" type="fixed">
    <origin rpy="0 0 0" xyz="0.8 1.8 0.0"/>
    <parent link="world_interface"/>
    <child link="robot1_pedestal_link"/>
  </joint>
  <link name="robot1_pedestal_link">
    <visual>
      <origin xyz="0 0 0.475"/>
      <geometry>
        <box size="0.3 0.3 0.95"/>
      </geometry>
      <material name="pedestal_color">
        <color rgba="0 0.1568627450980392 0.5254901960784314 1"/>
      </material>
    </visual>
    <collision>
      <origin xyz="0 0 0.475"/>
      <geometry>
        <box size="0.3 0.3 0.95"/>
      </geometry>
    </collision>
    <inertial>
      <mass value="500"/>
      <origin rpy="0 0 0" xyz="0 0 0"/>
      <inertia ixx="0.001" ixy="0" ixz="0" iyy="0.001" iyz="0" izz="0.001"/>
    </inertial>
  </link>
  <gazebo reference="robot1_pedestal_link">
    <material>Gazebo/Blue</material>
  </gazebo>
  <!-- franka robot 2 -->
  <!-- <xacro:arg name="arm_id_2" default="panda2"/>
  <xacro:arg name="use_cylinder_collision_model" default="true"/>
  <xacro:arg name="use_gazebo_sim" default="true"/>
  <xacro:arg name="parent2" default="robot2_pedestal_link"/> -->
  <!-- Load panda arm and hand -->
  <!-- <xacro:include filename="$(find franka_description)/robots/panda_arm.xacro" />
  <xacro:include filename="$(find franka_description)/robots/hand.xacro"/> -->
  <!-- Load gazebo control -->
  <!-- <xacro:if value="$(arg use_gazebo_sim)">
    <xacro:include filename="$(find franka_description)/robots/panda.gazebo.xacro"/>
    <xacro:include filename="$(find franka_description)/robots/panda.control.xacro"/>
  </xacro:if> -->
  <!-- <xacro:panda_arm xyz="0.05 0 0.95" rpy="0 0 0" connected_to="$(arg parent2)" arm_id="$(arg arm_id_2)" safety_distance="0.03" use_cylinder_collision_model="$(arg use_cylinder_collision_model)"/>
  <xacro:hand ns="$(arg arm_id_2)" rpy="0 0 ${-pi/4}" connected_to="$(arg arm_id_2)_link8" safety_distance="0.03" use_cylinder_collision_model="$(arg use_cylinder_collision_model)"/>

  <xacro:arm_gazebo arm_id="$(arg arm_id_2)"/>
  <xacro:arm_control arm_id="$(arg arm_id_2)"/>


  <xacro:include filename="$(find external_ros_models)/urdf/robot_pedestal/robot_pedestal.urdf.xacro"/>
  <xacro:robot_pedestal_urdf pedestal_prefix="robot2_" pedestal_parent="world_interface" pedestal_height="0.95">
    <origin xyz="0.8 3.0 0.0" rpy="0 0 0"/>
  </xacro:robot_pedestal_urdf>



  <xacro:include filename="$(find aau_lab_ros_models)/urdf/festo_straight_module/festo_straight_module.urdf.xacro"/>
  <xacro:festo_module_urdf module_prefix="module_1" festo_module_parent="world_interface">
    <origin xyz="1.5 1.8 0.0" rpy="0 0 0"/>
  </xacro:festo_module_urdf>
  <xacro:festo_module_urdf module_prefix="module_2" festo_module_parent="world_interface">
    <origin xyz="1.5 3.0 0.0" rpy="0 0 0"/>
  </xacro:festo_module_urdf> -->
  <!-- robot module -->
  <!-- <xacro:include filename="$(find aau_lab_ros_models)/urdf/festo_robot_module/festo_robot_module.urdf.xacro"/>
  <xacro:festo_module_urdf module_prefix="module_robot_1" festo_module_parent="world_interface">
    <origin xyz="1.5 0.6 0.0" rpy="0 0 0"/>
  </xacro:festo_module_urdf>

  <xacro:include filename="$(find aau_lab_ros_models)/urdf/festo_bypass_module/festo_bypass_module.urdf.xacro"/>
  <xacro:festo_module_urdf module_prefix="module_bypass_1" festo_module_parent="world_interface">
    <origin xyz="1.5 -0.6 0.0" rpy="0 0 0"/>
  </xacro:festo_module_urdf>

  <xacro:include filename="$(find aau_lab_ros_models)/urdf/festo_t_module/festo_t_module.urdf.xacro"/>
  <xacro:festo_module_urdf module_prefix="module_t_1" festo_module_parent="world_interface">
    <origin xyz="1.5 4.2 0.0" rpy="0 0 0"/>
  </xacro:festo_module_urdf> -->
  <!-- <xacro:include filename="$(find aau_lab_ros_models)/urdf/eu_pallet/eu_pallet.urdf.xacro"/>
  <xacro:eu_pallet_urdf eu_pallet_prefix="eu_pallet_1" eu_pallet_parent="world_interface">
    <origin xyz="3.5 4.2 0.0" rpy="0 0 0"/>
  </xacro:eu_pallet_urdf> -->
  <!-- left arm with gripper -->
  <!-- <xacro:panda_arm arm_id="$(arg arm_id_2)" connected_to="${parent}"  xyz="0 0.5 1" safety_distance="0.03"/>
  <xacro:hand ns="$(arg arm_id_2)" rpy="0 0 ${-pi/4}" connected_to="$(arg arm_id_2)_link8" safety_distance="0.03"/> -->
  <!-- <xacro:include filename="$(find external_ros_models)/urdf/robot_pedestal/robot_pedestal.urdf.xacro"/>
  <xacro:robot_pedestal_urdf pedestal_prefix="robot1_" pedestal_parent="world_interface" pedestal_height="0.95">
    <origin xyz="0.5 1.8 0.0" rpy="0 0 0"/>
  </xacro:robot_pedestal_urdf> -->
  <!-- <joint name="panda2_virtual_joint" type="fixed">
    <parent link="robot1_pedestal_link"/>
    <child link="${arm_id_2}_link0"/>
    <origin rpy="0 0 0" xyz="0.05 0 0.95"/>
    <dynamics damping="1.0"/>
  </joint> -->
  <!-- <joint name="robot1_pedestal_joint" type="fixed">
    <origin rpy="0 0 0" xyz="0.5 1.8 0.0"/>
    <parent link="world_interface"/>
    <child link="robot1_pedestal_link"/>
  </joint> -->
  <!-- <link name="robot1_pedestal_link">
    <visual>
      <origin xyz="0 0 0.475"/>
      <geometry>
        <box size="0.3 0.3 0.95"/>
      </geometry>
      <material name="pedestal_color">
        <color rgba="0 0.1568627450980392 0.5254901960784314 1"/>
      </material>
    </visual>
    <collision>
      <origin xyz="0 0 0.475"/>
      <geometry>
        <box size="0.3 0.3 0.95"/>
      </geometry>
    </collision>
    <inertial>
      <mass value="500"/>
      <origin rpy="0 0 0" xyz="0 0 0"/>
      <inertia ixx="0.001" ixy="0" ixz="0" iyy="0.001" iyz="0" izz="0.001"/>
    </inertial>
  </link> -->
</robot>
